<?xml version="1.0" ?>
<sdf version="1.7">
  <model name="fanuc_crx_10ia">
    <pose>0 0 0 0 0 0</pose>

    <!-- Base Link -->
    <link name="base">
      <pose>0 0 0.05 0 0 0</pose>
      <collision name="base_collision">
        <geometry>
          <cylinder>
            <radius>0.2</radius>
            <length>0.1</length>
          </cylinder>
        </geometry>
      </collision>
      <visual name="base_visual">
        <geometry>
          <cylinder>
            <radius>0.2</radius>
            <length>0.1</length>
          </cylinder>
        </geometry>
        <material>
          <ambient>0.7 0.7 0.7 1</ambient>
          <diffuse>0.7 0.7 0.7 1</diffuse>
        </material>
      </visual>
    </link>

    <!-- Joint 1 -->
    <joint name="joint_1" type="revolute">
      <parent>base</parent>
      <child>link_1</child>
      <axis>
        <xyz>0 0 1</xyz>
        <limit>
          <lower>-3.14159</lower>
          <upper>3.14159</upper>
        </limit>
        <dynamics>
          <damping>0.1</damping>
          <friction>0.1</friction>
        </dynamics>
      </axis>
    </joint>

    <!-- Link 1 -->
    <link name="link_1">
      <pose>0 0 0.3 0 0 0</pose>
      <collision name="link_1_collision">
        <geometry>
          <cylinder>
            <radius>0.08</radius>
            <length>0.6</length>
          </cylinder>
        </geometry>
      </collision>
      <visual name="link_1_visual">
        <geometry>
          <cylinder>
            <radius>0.08</radius>
            <length>0.6</length>
          </cylinder>
        </geometry>
        <material>
          <ambient>0.8 0.2 0.2 1</ambient>
          <diffuse>0.8 0.2 0.2 1</diffuse>
        </material>
      </visual>
    </link>

    <!-- Joint 2 -->
    <joint name="joint_2" type="revolute">
      <parent>link_1</parent>
      <child>link_2</child>
      <axis>
        <xyz>0 1 0</xyz>
        <limit>
          <lower>-1.57</lower>
          <upper>1.57</upper>
        </limit>
        <dynamics>
          <damping>0.1</damping>
          <friction>0.1</friction>
        </dynamics>
      </axis>
    </joint>

    <!-- Link 2 -->
    <link name="link_2">
      <pose>0 0 0.8 0 0 0</pose>
      <collision name="link_2_collision">
        <geometry>
          <box>
            <size>0.05 0.05 0.5</size>
          </box>
        </geometry>
      </collision>
      <visual name="link_2_visual">
        <geometry>
          <box>
            <size>0.05 0.05 0.5</size>
          </box>
        </geometry>
        <material>
          <ambient>0.2 0.8 0.2 1</ambient>
          <diffuse>0.2 0.8 0.2 1</diffuse>
        </material>
      </visual>
    </link>

    <!-- Joint 3 -->
    <joint name="joint_3" type="revolute">
      <parent>link_2</parent>
      <child>link_3</child>
      <axis>
        <xyz>0 -1 0</xyz>
        <limit>
          <lower>-3.14</lower>
          <upper>3.14</upper>
        </limit>
        <dynamics>
          <damping>0.1</damping>
          <friction>0.1</friction>
        </dynamics>
      </axis>
    </joint>

    <!-- Link 3 -->
    <link name="link_3">
      <pose>0 0 1.4 0 0 0</pose>
      <collision name="link_3_collision">
        <geometry>
          <cylinder>
            <radius>0.06</radius>
            <length>0.7</length>
          </cylinder>
        </geometry>
      </collision>
      <visual name="link_3_visual">
        <geometry>
          <cylinder>
            <radius>0.06</radius>
            <length>0.7</length>
          </cylinder>
        </geometry>
        <material>
          <ambient>0.2 0.2 0.8 1</ambient>
          <diffuse>0.2 0.2 0.8 1</diffuse>
        </material>
      </visual>
    </link>

    <!-- Joint 4 -->
    <joint name="joint_4" type="revolute">
      <parent>link_3</parent>
      <child>link_4</child>
      <axis>
        <xyz>-1 0 0</xyz>
        <limit>
          <lower>-3.14</lower>
          <upper>3.14</upper>
        </limit>
      </axis>
    </joint>

    <!-- Link 4 -->
    <link name="link_4">
      <pose>0 0 1.8 0 0 0</pose>
      <collision name="link_4_collision">
        <geometry>
          <box>
            <size>0.04 0.04 0.4</size>
          </box>
        </geometry>
      </collision>
      <visual name="link_4_visual">
        <geometry>
          <box>
            <size>0.04 0.04 0.4</size>
          </box>
        </geometry>
      </visual>
    </link>

  </model>
</sdf>
